<?xml version="1.0" ?>
<!-- =================================================================================== -->
<!-- |    This document was autogenerated by xacro from dual_manipulator.xacro         | -->
<!-- |    EDITING THIS FILE BY HAND IS NOT RECOMMENDED                                 | -->
<!-- =================================================================================== -->
<robot name="dual" xmlns:xacro="http://ros.org/wiki/xacro">
  <!--degrees to radians-->
  <link name="firstbase_link">
    <visual>
      <origin rpy="0 0 0" xyz="0 0 0"/>
      <geometry>
        <mesh filename="package://motoman_sia5d_support/meshes/sia5d/visual/base.dae"/>
      </geometry>
    </visual>
    <collision>
      <origin rpy="0 0 0" xyz="0 0 0"/>
      <geometry>
        <mesh filename="package://motoman_sia5d_support/meshes/sia5d/collision/base.dae"/>
      </geometry>
    </collision>
  </link>
  <link name="firstlink_s">
    <visual>
      <origin rpy="0 0 0" xyz="0 0 0"/>
      <geometry>
        <mesh filename="package://motoman_sia5d_support/meshes/sia5d/visual/link_s.dae"/>
      </geometry>
    </visual>
    <collision>
      <origin rpy="0 0 0" xyz="0 0 0"/>
      <geometry>
        <mesh filename="package://motoman_sia5d_support/meshes/sia5d/collision/link_s.dae"/>
      </geometry>
    </collision>
  </link>
  <joint name="firstjoint_s" type="revolute">
    <origin rpy="0 0 0" xyz="0 0 0.31"/>
    <!--r=${90*deg}-->
    <parent link="firstbase_link"/>
    <child link="firstlink_s"/>
    <axis xyz="0 0 1"/>
    <limit effort="0" lower="-3.14159274" upper="3.14159274" velocity="3.4906586"/>
  </joint>
  <link name="firstlink_l">
    <visual>
      <origin rpy="0 0 0" xyz="0 0 0"/>
      <geometry>
        <mesh filename="package://motoman_sia5d_support/meshes/sia5d/visual/link_l.dae"/>
      </geometry>
    </visual>
    <collision>
      <origin rpy="0 0 0" xyz="0 0 0"/>
      <geometry>
        <mesh filename="package://motoman_sia5d_support/meshes/sia5d/collision/link_l.dae"/>
      </geometry>
    </collision>
  </link>
  <joint name="firstjoint_l" type="revolute">
    <origin rpy="0 0 0" xyz="0 0 0"/>
    <parent link="firstlink_s"/>
    <child link="firstlink_l"/>
    <axis xyz="0 1 0"/>
    <limit effort="0" lower="-1.91986223" upper="1.91986223" velocity="3.4906586"/>
  </joint>
  <link name="firstlink_e">
    <visual>
      <origin rpy="0 0 0" xyz="0 0 0"/>
      <geometry>
        <mesh filename="package://motoman_sia5d_support/meshes/sia5d/visual/link_e.dae"/>
      </geometry>
    </visual>
    <collision>
      <origin rpy="0 0 0" xyz="0 0 0"/>
      <geometry>
        <mesh filename="package://motoman_sia5d_support/meshes/sia5d/collision/link_e.dae"/>
      </geometry>
    </collision>
  </link>
  <joint name="firstjoint_e" type="revolute">
    <origin rpy="0 0 0" xyz="0 0 0.27"/>
    <parent link="firstlink_l"/>
    <child link="firstlink_e"/>
    <axis xyz="0 0 1"/>
    <limit effort="0" lower="-2.96705981" upper="2.96705981" velocity="3.4906586"/>
  </joint>
  <link name="firstlink_u">
    <visual>
      <origin rpy="0 0 0" xyz="0 0 0"/>
      <geometry>
        <mesh filename="package://motoman_sia5d_support/meshes/sia5d/visual/link_u.dae"/>
      </geometry>
    </visual>
    <collision>
      <origin rpy="0 0 0" xyz="0 0 0"/>
      <geometry>
        <mesh filename="package://motoman_sia5d_support/meshes/sia5d/collision/link_u.dae"/>
      </geometry>
    </collision>
  </link>
  <joint name="firstjoint_u" type="revolute">
    <origin rpy="0 0 0" xyz="0.085 0 0"/>
    <parent link="firstlink_e"/>
    <child link="firstlink_u"/>
    <axis xyz="0 1 0"/>
    <limit effort="0" lower="-1.57079637" upper="2.007128695" velocity="3.4906586"/>
  </joint>
  <link name="firstlink_r">
    <visual>
      <origin rpy="0 0 0" xyz="0 0 0"/>
      <geometry>
        <mesh filename="package://motoman_sia5d_support/meshes/sia5d/visual/link_r.dae"/>
      </geometry>
    </visual>
    <collision>
      <origin rpy="0 0 0" xyz="0 0 0"/>
      <geometry>
        <mesh filename="package://motoman_sia5d_support/meshes/sia5d/collision/link_r.dae"/>
      </geometry>
    </collision>
  </link>
  <joint name="firstjoint_r" type="revolute">
    <origin rpy="0 0 0" xyz="0.27 0 0.06"/>
    <parent link="firstlink_u"/>
    <child link="firstlink_r"/>
    <axis xyz="-1 0 0"/>
    <limit effort="0" lower="-1.57079637" upper="1.57079637" velocity="3.4906586"/>
  </joint>
  <link name="firstlink_b">
    <visual>
      <origin rpy="0 0 0" xyz="0 0 0"/>
      <geometry>
        <mesh filename="package://motoman_sia5d_support/meshes/sia5d/visual/link_b.dae"/>
      </geometry>
    </visual>
    <collision>
      <origin rpy="0 0 0" xyz="0 0 0"/>
      <geometry>
        <mesh filename="package://motoman_sia5d_support/meshes/sia5d/collision/link_b.dae"/>
      </geometry>
    </collision>
  </link>
  <joint name="firstjoint_b" type="revolute">
    <origin rpy="0 0 0" xyz="0 0 0"/>
    <parent link="firstlink_r"/>
    <child link="firstlink_b"/>
    <axis xyz="0 1 0"/>
    <limit effort="0" lower="-1.91986223" upper="1.91986223" velocity="4.01425739"/>
  </joint>
  <link name="firstlink_t">
    <visual>
      <origin rpy="0 0 0" xyz="0 0 0"/>
      <geometry>
        <mesh filename="package://motoman_sia5d_support/meshes/sia5d/visual/link_t.dae"/>
      </geometry>
    </visual>
    <collision>
      <origin rpy="0 0 0" xyz="0 0 0"/>
      <geometry>
        <mesh filename="package://motoman_sia5d_support/meshes/sia5d/collision/link_t.dae"/>
      </geometry>
    </collision>
  </link>
  <joint name="firstjoint_t" type="revolute">
    <origin rpy="0 0 0" xyz="0.134 0 0"/>
    <parent link="firstlink_b"/>
    <child link="firstlink_t"/>
    <axis xyz="-1 0 0"/>
    <limit effort="0" lower="-1.57079637" upper="1.57079637" velocity="6.10865255"/>
  </joint>
  <link name="firsttool0"/>
  <joint name="firstlink_t-tool0" type="fixed">
    <origin rpy="-1.57079637 -1.57079637 -1.57079637" xyz="0.011 0 0"/>
    <parent link="firstlink_t"/>
    <child link="firsttool0"/>
  </joint>
  <!-- ROS base_link (via link_l) to Motoman Robot (not Base) Frame transform -->
  <link name="firstbase"/>
  <joint name="firstlink_l-base" type="fixed">
    <origin rpy="0 0 0" xyz="0 0 0"/>
    <parent link="firstlink_l"/>
    <child link="firstbase"/>
  </joint>
  <link name="secondbase_link">
    <visual>
      <origin rpy="0 0 0" xyz="0 0 0"/>
      <geometry>
        <mesh filename="package://motoman_sia5d_support/meshes/sia5d/visual/base.dae"/>
      </geometry>
    </visual>
    <collision>
      <origin rpy="0 0 0" xyz="0 0 0"/>
      <geometry>
        <mesh filename="package://motoman_sia5d_support/meshes/sia5d/collision/base.dae"/>
      </geometry>
    </collision>
  </link>
  <link name="secondlink_s">
    <visual>
      <origin rpy="0 0 0" xyz="0 0 0"/>
      <geometry>
        <mesh filename="package://motoman_sia5d_support/meshes/sia5d/visual/link_s.dae"/>
      </geometry>
    </visual>
    <collision>
      <origin rpy="0 0 0" xyz="0 0 0"/>
      <geometry>
        <mesh filename="package://motoman_sia5d_support/meshes/sia5d/collision/link_s.dae"/>
      </geometry>
    </collision>
  </link>
  <joint name="secondjoint_s" type="revolute">
    <origin rpy="0 0 0" xyz="0 0 0.31"/>
    <!--r=${90*deg}-->
    <parent link="secondbase_link"/>
    <child link="secondlink_s"/>
    <axis xyz="0 0 1"/>
    <limit effort="0" lower="-3.14159274" upper="3.14159274" velocity="3.4906586"/>
  </joint>
  <link name="secondlink_l">
    <visual>
      <origin rpy="0 0 0" xyz="0 0 0"/>
      <geometry>
        <mesh filename="package://motoman_sia5d_support/meshes/sia5d/visual/link_l.dae"/>
      </geometry>
    </visual>
    <collision>
      <origin rpy="0 0 0" xyz="0 0 0"/>
      <geometry>
        <mesh filename="package://motoman_sia5d_support/meshes/sia5d/collision/link_l.dae"/>
      </geometry>
    </collision>
  </link>
  <joint name="secondjoint_l" type="revolute">
    <origin rpy="0 0 0" xyz="0 0 0"/>
    <parent link="secondlink_s"/>
    <child link="secondlink_l"/>
    <axis xyz="0 1 0"/>
    <limit effort="0" lower="-1.91986223" upper="1.91986223" velocity="3.4906586"/>
  </joint>
  <link name="secondlink_e">
    <visual>
      <origin rpy="0 0 0" xyz="0 0 0"/>
      <geometry>
        <mesh filename="package://motoman_sia5d_support/meshes/sia5d/visual/link_e.dae"/>
      </geometry>
    </visual>
    <collision>
      <origin rpy="0 0 0" xyz="0 0 0"/>
      <geometry>
        <mesh filename="package://motoman_sia5d_support/meshes/sia5d/collision/link_e.dae"/>
      </geometry>
    </collision>
  </link>
  <joint name="secondjoint_e" type="revolute">
    <origin rpy="0 0 0" xyz="0 0 0.27"/>
    <parent link="secondlink_l"/>
    <child link="secondlink_e"/>
    <axis xyz="0 0 1"/>
    <limit effort="0" lower="-2.96705981" upper="2.96705981" velocity="3.4906586"/>
  </joint>
  <link name="secondlink_u">
    <visual>
      <origin rpy="0 0 0" xyz="0 0 0"/>
      <geometry>
        <mesh filename="package://motoman_sia5d_support/meshes/sia5d/visual/link_u.dae"/>
      </geometry>
    </visual>
    <collision>
      <origin rpy="0 0 0" xyz="0 0 0"/>
      <geometry>
        <mesh filename="package://motoman_sia5d_support/meshes/sia5d/collision/link_u.dae"/>
      </geometry>
    </collision>
  </link>
  <joint name="secondjoint_u" type="revolute">
    <origin rpy="0 0 0" xyz="0.085 0 0"/>
    <parent link="secondlink_e"/>
    <child link="secondlink_u"/>
    <axis xyz="0 1 0"/>
    <limit effort="0" lower="-1.57079637" upper="2.007128695" velocity="3.4906586"/>
  </joint>
  <link name="secondlink_r">
    <visual>
      <origin rpy="0 0 0" xyz="0 0 0"/>
      <geometry>
        <mesh filename="package://motoman_sia5d_support/meshes/sia5d/visual/link_r.dae"/>
      </geometry>
    </visual>
    <collision>
      <origin rpy="0 0 0" xyz="0 0 0"/>
      <geometry>
        <mesh filename="package://motoman_sia5d_support/meshes/sia5d/collision/link_r.dae"/>
      </geometry>
    </collision>
  </link>
  <joint name="secondjoint_r" type="revolute">
    <origin rpy="0 0 0" xyz="0.27 0 0.06"/>
    <parent link="secondlink_u"/>
    <child link="secondlink_r"/>
    <axis xyz="-1 0 0"/>
    <limit effort="0" lower="-1.57079637" upper="1.57079637" velocity="3.4906586"/>
  </joint>
  <link name="secondlink_b">
    <visual>
      <origin rpy="0 0 0" xyz="0 0 0"/>
      <geometry>
        <mesh filename="package://motoman_sia5d_support/meshes/sia5d/visual/link_b.dae"/>
      </geometry>
    </visual>
    <collision>
      <origin rpy="0 0 0" xyz="0 0 0"/>
      <geometry>
        <mesh filename="package://motoman_sia5d_support/meshes/sia5d/collision/link_b.dae"/>
      </geometry>
    </collision>
  </link>
  <joint name="secondjoint_b" type="revolute">
    <origin rpy="0 0 0" xyz="0 0 0"/>
    <parent link="secondlink_r"/>
    <child link="secondlink_b"/>
    <axis xyz="0 1 0"/>
    <limit effort="0" lower="-1.91986223" upper="1.91986223" velocity="4.01425739"/>
  </joint>
  <link name="secondlink_t">
    <visual>
      <origin rpy="0 0 0" xyz="0 0 0"/>
      <geometry>
        <mesh filename="package://motoman_sia5d_support/meshes/sia5d/visual/link_t.dae"/>
      </geometry>
    </visual>
    <collision>
      <origin rpy="0 0 0" xyz="0 0 0"/>
      <geometry>
        <mesh filename="package://motoman_sia5d_support/meshes/sia5d/collision/link_t.dae"/>
      </geometry>
    </collision>
  </link>
  <joint name="secondjoint_t" type="revolute">
    <origin rpy="0 0 0" xyz="0.134 0 0"/>
    <parent link="secondlink_b"/>
    <child link="secondlink_t"/>
    <axis xyz="-1 0 0"/>
    <limit effort="0" lower="-1.57079637" upper="1.57079637" velocity="6.10865255"/>
  </joint>
  <link name="secondtool0"/>
  <joint name="secondlink_t-tool0" type="fixed">
    <origin rpy="-1.57079637 -1.57079637 -1.57079637" xyz="0.011 0 0"/>
    <parent link="secondlink_t"/>
    <child link="secondtool0"/>
  </joint>
  <!-- ROS base_link (via link_l) to Motoman Robot (not Base) Frame transform -->
  <link name="secondbase"/>
  <joint name="secondlink_l-base" type="fixed">
    <origin rpy="0 0 0" xyz="0 0 0"/>
    <parent link="secondlink_l"/>
    <child link="secondbase"/>
  </joint>
  <material name="blue">
    <color rgba="0 0 .8 1"/>
  </material>
  <link name="base_box">
    <visual>
      <geometry>
        <box size="1 0.5 0.2"/>
      </geometry>
      <origin rpy="0 0 0" xyz="0 0 0.1"/>
      <material name="blue"/>
    </visual>
    <collision>
      <geometry>
        <box size="1 0.5 0.2"/>
      </geometry>
    </collision>
    <inertial>
      <mass value="10"/>
      <inertia ixx="1.0" ixy="0.0" ixz="0.0" iyy="1.0" iyz="0.0" izz="1.0"/>
    </inertial>
  </link>
  <joint name="base_joint_left" type="fixed">
    <parent link="base_box"/>
    <child link="firstbase_link"/>
    <origin xyz="-0.3 0 0.2"/>
  </joint>
  <joint name="base_joint_right" type="fixed">
    <parent link="base_box"/>
    <child link="secondbase_link"/>
    <origin xyz="0.3 0 0.2"/>
  </joint>
</robot>

